<?xml version="1.0"?>
<robot xmlns:xacro="http://www.ros.org/wiki/xacro" >

    <xacro:include filename="inertial_macros.xacro"/>
    <xacro:arg name="mesh_enabled" default="false" />
    <xacro:arg name="robot_namespace" default="/"/>

    <material name="white">
        <color rgba="1 1 1 1" />
    </material>

    <material name="orange">
        <color rgba="1 0.3 0.1 1"/>
    </material>

    <material name="blue">
        <color rgba="0.2 0.2 1 1"/>
    </material>

    <material name="black">
        <color rgba="0 0 0 1"/>
    </material>

    <!-- BASE LINK -->

    <link name="base_link">

    </link>


    <!-- CHASSIS LINK -->

    <joint name="chassis_joint" type="fixed">
        <parent link="base_link"/>
        <child link="chassis"/>
        <origin xyz="-0.011 0.21 -0.17"/>
    </joint>

    <link name="chassis">
        <visual>
            <origin xyz="-0.09 0.1575 0" rpy="1.5708 0 0"/>
            <geometry>
                <!-- <box size="0.3 0.3 0.15"/> -->
                <mesh
                    filename="package://my_mobile_robot/meshes/Assemby.STL"
                    scale="0.001 0.001 0.001" />
            </geometry>
            <material name="white"/>
        </visual>
        <collision>
            <origin xyz="-0.09 0.1575 0" rpy="1.5708 0 0"/>
            <geometry>
                <!-- <box size="0.3 0.3 0.15"/> -->
                <mesh
                    filename="package://my_mobile_robot/meshes/Assemby.STL"
                    scale="0.001 0.001 0.001" />
            </geometry>
        </collision>
        <xacro:macro name="default_inertial" params="mass">
            <inertial>
                <origin xyz="0.15 0 0.075" rpy="0 0 0"/>
                <mass value="1" />
                <inertia ixx="0.001" ixy="0" ixz="0" iyy="0.001" iyz="0" izz="0.001" />
            </inertial>
        </xacro:macro>
    </link>
    
    <!-- LEFT WHEEL LINK -->

    <joint name="left_wheel" type="continuous">
        <parent link="base_link"/>
        <child link="left_wheel_link"/>
        <origin xyz="-0.033 0.1 0.05" rpy="-${pi/2} 0 0" /> 
        <axis xyz="0 0 1"/>
        <dynamics damping="0.5" friction="100.0" />
    </joint>

    <link name="left_wheel_link">
        <visual>
            <origin xyz="0 0 0" rpy="0 0 0"/>
            <geometry>
                <!-- <cylinder radius="0.05" length="0.04"/> -->
                <mesh
                    filename="package://my_mobile_robot/meshes/roll.STL"
                    scale="0.001 0.001 0.001" />
            </geometry>
            <material name="blue"/>
        </visual>
        <collision>
            <origin xyz="0 0 0" rpy="0 0 0"/>
            <geometry>
                <!-- <cylinder radius="0.05" length="0.04"/> -->
                <mesh
                    filename="package://my_mobile_robot/meshes/roll.STL"
                    scale="0.001 0.001 0.001" />
            </geometry>
        </collision>
        <xacro:macro name="default_inertial" params="mass">
            <inertial>
                <origin xyz="0 0.1 0" rpy="0 0 0"/>
                <mass value="1" />
                <inertia ixx="0.001" ixy="0" ixz="0" iyy="0.001" iyz="0" izz="0.001" />
            </inertial>
        </xacro:macro>
    </link>

    <transmission name="left_wheel_trans" type="SimpleTransmission">
        <type>transmission_interface/SimpleTransmission</type>
        <actuator name="left_wheel_motor">
            <mechanicalReduction>1</mechanicalReduction>
        </actuator>
        <joint name="left_wheel">
            <hardwareInterface>hardware_interface/VelocityJointInterface</hardwareInterface>
        </joint>
    </transmission>

    <!-- RIGHT WHEEL LINK -->

    <joint name="right_wheel" type="continuous">
        <parent link="base_link"/>
        <child link="right_wheel_link"/>
        <origin xyz="-0.033 -.1 -0.02" rpy="${pi/2} 0 0" />
        <axis xyz="0 0 -1"/>
        <dynamics damping="0.5" friction="100.0" />
    </joint>

    <link name="right_wheel_link">
        <visual>
            <origin xyz="0 0 0" rpy="0 0 0"/>
            <geometry>
                <!-- <cylinder radius="0.05" length="0.04"/> -->
                <mesh
                    filename="package://my_mobile_robot/meshes/roll.STL"
                    scale="0.001 0.001 0.001" />
            </geometry>
            <material name="blue"/>
        </visual>
        <collision>
            <origin xyz="0 0 0" rpy="0 0 0"/>
            <geometry>
                <!-- <cylinder radius="0.05" length="0.04"/> -->
                <mesh
                    filename="package://my_mobile_robot/meshes/roll.STL"
                    scale="0.001 0.001 0.001" />
            </geometry>
        </collision>
        <xacro:macro name="default_inertial" params="mass">
            <inertial>
                <origin xyz="0 0.1 0" rpy="0 0 0"/>
                <mass value="1" />
                <inertia ixx="0.001" ixy="0" ixz="0" iyy="0.001" iyz="0" izz="0.001" />
            </inertial>
        </xacro:macro>
    </link>
    <transmission name="right_wheel_trans" type="SimpleTransmission">
        <type>transmission_interface/SimpleTransmission</type>
        <actuator name="right_wheel_motor">
            <mechanicalReduction>1</mechanicalReduction>
        </actuator>
        <joint name="right_wheel">
            <hardwareInterface>hardware_interface/VelocityJointInterface</hardwareInterface>
        </joint>
    </transmission>

    
      
</robot>
